Workbook

Sheet cross_sector_insights_tp
A1: ID | B1: Name | C1: Scope | D1: Perspective | E1: s001:Construction | F1: s002:Manufacturing | G1: s003:Health Services | H1: field
A2: TP01 | B2: Model-based Knowledge Representation and Simulation | C2: Uses BIM, 3D/4D models, engineering simulations, virtual models, and computational scenarios to represent assets, environments, construction processes, system behavior, and performance relationships. | D2: Digital Codification | E2: {=IFERROR(INDEX(s001_insights!F:F,MATCH("s001M01"&A2,s001_insights!A:A,0)),"")} -> TK06 Trained Sensory and Perceptual Recognition | F2: {=IFERROR(INDEX(s002_insights!F:F,MATCH("s002M01"&A2,s002_insights!A:A,0)),"")} | G2: {=IFERROR(INDEX(s003_insights!F:F,MATCH("s003M01"&A2,s003_insights!A:A,0)),"")} -> TK05 Practised Motor and Tool-Operation Skill TK06 Trained Sensory and Perceptual Recognition TK10 Shared Professional Norms and Standards of Judgment | H2: =3-COUNTIF(E2:G2,"") -> 2 | J2: <TP01, TK06> | K2: <TP01, TK05> <TP01, TK10>
A3: TP02 | B3: Spatial Knowledge Capture and Geospatial Reconstruction | C3: Uses UAVs, photogrammetry, laser scanning, GIS, and surveying technologies to convert physical and spatial conditions into measurable digital representations. | D3: Digital Codification | E3: {=IFERROR(INDEX(s001_insights!F:F,MATCH("s001M01"&A3,s001_insights!A:A,0)),"")} | F3: {=IFERROR(INDEX(s002_insights!F:F,MATCH("s002M01"&A3,s002_insights!A:A,0)),"")} | G3: {=IFERROR(INDEX(s003_insights!F:F,MATCH("s003M01"&A3,s003_insights!A:A,0)),"")} | H3: =3-COUNTIF(E3:G3,"") -> 0
A4: TP03 | B4: Situated Experiential Learning through Extended Reality | C4: Uses VR, AR, MR, CAVE, or hybrid XR environments to support embodied rehearsal, contextual guidance, historical interpretation, hazard recognition, and situated knowledge transfer. | D4: Experiential Amplification | E4: {=IFERROR(INDEX(s001_insights!F:F,MATCH("s001M01"&A4,s001_insights!A:A,0)),"")} -> TK05 Practised Motor and Tool-Operation Skill TK06 Trained Sensory and Perceptual Recognition TK07 Embodied Posture, Balance, and Spatial Control TK08 Immediate Embodied Response to Changing Conditions TK10 Shared Professional Norms and Standards of Judgment | F4: {=IFERROR(INDEX(s002_insights!F:F,MATCH("s002M01"&A4,s002_insights!A:A,0)),"")} -> TK04 Unrecognized or Unarticulated Personal Know-how TK05 Practised Motor and Tool-Operation Skill TK06 Trained Sensory and Perceptual Recognition TK07 Embodied Posture, Balance, and Spatial Control | G4: {=IFERROR(INDEX(s003_insights!F:F,MATCH("s003M01"&A4,s003_insights!A:A,0)),"")} -> TK05 Practised Motor and Tool-Operation Skill TK06 Trained Sensory and Perceptual Recognition TK08 Immediate Embodied Response to Changing Conditions TK11 Informal Coordination, Communication, and Escalation Know-how TK10 Shared Professional Norms and Standards of Judgment | H4: =3-COUNTIF(E4:G4,"") -> 3 | I4: <TP03, TK05> <TP03, TK06> | J4: <TP03, TK07> <TP03, TK08> <TP03, TK10> | K4: <TP03, TK04> <TP03, TK11>
A5: TP04 | B5: Interactive Consequence Learning and Digital Feedback | C5: Uses responsive simulations, animations, indicators, interfaces, or multisensory feedback to make relationships between actions, system states, and consequences experientially perceptible. | D5: Experiential Amplification | E5: {=IFERROR(INDEX(s001_insights!F:F,MATCH("s001M01"&A5,s001_insights!A:A,0)),"")} | F5: {=IFERROR(INDEX(s002_insights!F:F,MATCH("s002M01"&A5,s002_insights!A:A,0)),"")} -> TK05 Practised Motor and Tool-Operation Skill | G5: {=IFERROR(INDEX(s003_insights!F:F,MATCH("s003M01"&A5,s003_insights!A:A,0)),"")} -> TK10 Shared Professional Norms and Standards of Judgment | H5: =3-COUNTIF(E5:G5,"") -> 2
A6: TP05 | B6: Real-time Condition Intelligence through IoT Monitoring | C6: Uses connected sensors and real-time data streams to capture building performance, occupancy, environmental conditions, and operational states. | D6: Digital Codification | E6: {=IFERROR(INDEX(s001_insights!F:F,MATCH("s001M01"&A6,s001_insights!A:A,0)),"")} | F6: {=IFERROR(INDEX(s002_insights!F:F,MATCH("s002M01"&A6,s002_insights!A:A,0)),"")} | G6: {=IFERROR(INDEX(s003_insights!F:F,MATCH("s003M01"&A6,s003_insights!A:A,0)),"")} | H6: =3-COUNTIF(E6:G6,"") -> 0
A7: TP06 | B7: Worker Activity and State Capture through Wearable Sensors and Cameras | C7: Uses IMUs, wearable sensors, eye trackers, cameras, and video analysis to record workers’ movement, posture, gaze, workload, task sequences, and situated work activities. | D7: Digital Codification | E7: {=IFERROR(INDEX(s001_insights!F:F,MATCH("s001M01"&A7,s001_insights!A:A,0)),"")} -> TK06 Trained Sensory and Perceptual Recognition TK07 Embodied Posture, Balance, and Spatial Control | F7: {=IFERROR(INDEX(s002_insights!F:F,MATCH("s002M01"&A7,s002_insights!A:A,0)),"")} -> TK04 Unrecognized or Unarticulated Personal Know-how TK05 Practised Motor and Tool-Operation Skill TK06 Trained Sensory and Perceptual Recognition TK07 Embodied Posture, Balance, and Spatial Control | G7: {=IFERROR(INDEX(s003_insights!F:F,MATCH("s003M01"&A7,s003_insights!A:A,0)),"")} | H7: =3-COUNTIF(E7:G7,"") -> 2 | I7: <TP06, TK06> <TP06, TK07>
A8: TP07 | B8: Algorithmic Pattern Discovery and Prediction | C8: Uses AI, machine learning, NLP, statistical learning, or rule-based algorithms to derive classifications, forecasts, detected patterns, and predicted conditions from data. | D8: Digital Codification | E8: {=IFERROR(INDEX(s001_insights!F:F,MATCH("s001M01"&A8,s001_insights!A:A,0)),"")} -> TK06 Trained Sensory and Perceptual Recognition TK10 Shared Professional Norms and Standards of Judgment | F8: {=IFERROR(INDEX(s002_insights!F:F,MATCH("s002M01"&A8,s002_insights!A:A,0)),"")} -> TK02 Knowledge Conveyed Through Examples or Demonstration TK04 Unrecognized or Unarticulated Personal Know-how TK05 Practised Motor and Tool-Operation Skill TK06 Trained Sensory and Perceptual Recognition | G8: {=IFERROR(INDEX(s003_insights!F:F,MATCH("s003M01"&A8,s003_insights!A:A,0)),"")} -> TK06 Trained Sensory and Perceptual Recognition TK10 Shared Professional Norms and Standards of Judgment | H8: =3-COUNTIF(E8:G8,"") -> 3 | I8: <TP07, TK06> | J8: <TP07, TK10>
A9: TP08 | B9: Generative Knowledge Synthesis and Content Production | C9: Uses generative AI to combine requirements, contextual data, and retrieved knowledge into new drafts, reports, explanations, summaries, or recommendations. | D9: Digital Codification | E9: {=IFERROR(INDEX(s001_insights!F:F,MATCH("s001M01"&A9,s001_insights!A:A,0)),"")} -> TK12 Organizational Culture and Unwritten Working Practices | F9: {=IFERROR(INDEX(s002_insights!F:F,MATCH("s002M01"&A9,s002_insights!A:A,0)),"")} -> TK06 Trained Sensory and Perceptual Recognition TK07 Embodied Posture, Balance, and Spatial Control TK12 Organizational Culture and Unwritten Working Practices | G9: {=IFERROR(INDEX(s003_insights!F:F,MATCH("s003M01"&A9,s003_insights!A:A,0)),"")} | H9: =3-COUNTIF(E9:G9,"") -> 2 | J9: <TP08, TK12>
A10: TP09 | B10: Semantic Knowledge Structuring and Retrieval | C10: Uses knowledge graphs, semantic metadata, embeddings, vector databases, and meaning-based search to represent knowledge relationships and retrieve contextually relevant information. | D10: Digital Codification | E10: {=IFERROR(INDEX(s001_insights!F:F,MATCH("s001M01"&A10,s001_insights!A:A,0)),"")} -> TK05 Practised Motor and Tool-Operation Skill | F10: {=IFERROR(INDEX(s002_insights!F:F,MATCH("s002M01"&A10,s002_insights!A:A,0)),"")} -> TK12 Organizational Culture and Unwritten Working Practices | G10: {=IFERROR(INDEX(s003_insights!F:F,MATCH("s003M01"&A10,s003_insights!A:A,0)),"")} -> TK02 Knowledge Conveyed Through Examples or Demonstration TK05 Practised Motor and Tool-Operation Skill TK10 Shared Professional Norms and Standards of Judgment TK09 Shared Professional Language and Contextual Meaning | H10: =3-COUNTIF(E10:G10,"") -> 3 | J10: <TP09, TK05>
A11: TP10 | B11: Database-supported Project Knowledge Archiving | C11: Preserves and retrieves codified project records, narratives, lessons learned, safety information, and operational knowledge through databases, data warehouses, or conventional KMS repositories. | D11: Digital Codification | E11: {=IFERROR(INDEX(s001_insights!F:F,MATCH("s001M01"&A11,s001_insights!A:A,0)),"")} -> TK02 Knowledge Conveyed Through Examples or Demonstration TK04 Unrecognized or Unarticulated Personal Know-how TK05 Practised Motor and Tool-Operation Skill TK10 Shared Professional Norms and Standards of Judgment TK11 Informal Coordination, Communication, and Escalation Know-how TK12 Organizational Culture and Unwritten Working Practices | F11: {=IFERROR(INDEX(s002_insights!F:F,MATCH("s002M01"&A11,s002_insights!A:A,0)),"")} -> TK04 Unrecognized or Unarticulated Personal Know-how TK05 Practised Motor and Tool-Operation Skill | G11: {=IFERROR(INDEX(s003_insights!F:F,MATCH("s003M01"&A11,s003_insights!A:A,0)),"")} -> TK09 Shared Professional Language and Contextual Meaning | H11: =3-COUNTIF(E11:G11,"") -> 3 | J11: <TP10, TK04> <TP10, TK05>
A12: TP11 | B12: Collaborative Knowledge Co-creation through Digital Platforms | C12: Uses portals, messaging systems, shared virtual environments, and online collaboration platforms to support peer exchange, collective interpretation, user contribution, and shared knowledge construction. | D12: Experiential Amplification | E12: {=IFERROR(INDEX(s001_insights!F:F,MATCH("s001M01"&A12,s001_insights!A:A,0)),"")} | F12: {=IFERROR(INDEX(s002_insights!F:F,MATCH("s002M01"&A12,s002_insights!A:A,0)),"")} -> TK04 Unrecognized or Unarticulated Personal Know-how TK09 Shared Professional Language and Contextual Meaning TK12 Organizational Culture and Unwritten Working Practices | G12: {=IFERROR(INDEX(s003_insights!F:F,MATCH("s003M01"&A12,s003_insights!A:A,0)),"")} -> TK02 Knowledge Conveyed Through Examples or Demonstration TK04 Unrecognized or Unarticulated Personal Know-how TK10 Shared Professional Norms and Standards of Judgment | H12: =3-COUNTIF(E12:G12,"") -> 2 | J12: <TP11, TK04>
A13: TP12 | B13: Multimedia and Blended Knowledge Internalization | C13: Combines digital content, interactive media, online resources, and face-to-face or workplace activities to strengthen demonstration, participation, and knowledge internalization. | D13: Experiential Amplification | E13: {=IFERROR(INDEX(s001_insights!F:F,MATCH("s001M01"&A13,s001_insights!A:A,0)),"")} -> TK05 Practised Motor and Tool-Operation Skill TK11 Informal Coordination, Communication, and Escalation Know-how | F13: {=IFERROR(INDEX(s002_insights!F:F,MATCH("s002M01"&A13,s002_insights!A:A,0)),"")} -> TK05 Practised Motor and Tool-Operation Skill TK10 Shared Professional Norms and Standards of Judgment | G13: {=IFERROR(INDEX(s003_insights!F:F,MATCH("s003M01"&A13,s003_insights!A:A,0)),"")} -> TK05 Practised Motor and Tool-Operation Skill | H13: =3-COUNTIF(E13:G13,"") -> 3 | J13: <TP12, TK05>
A14: TP13 | B14: Criteria-based Performance Evaluation and Ranking | C14: Measures, compares, scores, or ranks learners, models, interventions, and alternatives using predefined criteria, indicators, benchmarks, or performance metrics. | D14: Digital Codification | E14: {=IFERROR(INDEX(s001_insights!F:F,MATCH("s001M01"&A14,s001_insights!A:A,0)),"")} -> TK10 Shared Professional Norms and Standards of Judgment | F14: {=IFERROR(INDEX(s002_insights!F:F,MATCH("s002M01"&A14,s002_insights!A:A,0)),"")} -> TK05 Practised Motor and Tool-Operation Skill TK10 Shared Professional Norms and Standards of Judgment | G14: {=IFERROR(INDEX(s003_insights!F:F,MATCH("s003M01"&A14,s003_insights!A:A,0)),"")} -> TK12 Organizational Culture and Unwritten Working Practices | H14: =3-COUNTIF(E14:G14,"") -> 3 | J14: <TP13, TK10>
A15: TP15 | B15: Distributed-Ledger-enabled Transaction Assurance and Traceability | C15: Uses blockchain or distributed-ledger technologies to create verifiable transaction records, strengthen provenance and supply-chain traceability, validate products, and automate trusted exchanges through smart contracts or related mechanisms. | D15: Digital Codification | E15: {=IFERROR(INDEX(s001_insights!F:F,MATCH("s001M01"&A15,s001_insights!A:A,0)),"")} | F15: {=IFERROR(INDEX(s002_insights!F:F,MATCH("s002M01"&A15,s002_insights!A:A,0)),"")} | G15: {=IFERROR(INDEX(s003_insights!F:F,MATCH("s003M01"&A15,s003_insights!A:A,0)),"")} -> TK04 Unrecognized or Unarticulated Personal Know-how | H15: =3-COUNTIF(E15:G15,"") -> 1
A16: TP16 | B16: Gamified Procedural and Scenario-based Learning | C16: Uses structured games, quizzes, cards, role-playing scenarios, and realistic problem cases to help learners reconstruct procedural sequences, apply operational criteria, recognize errors, and select appropriate responses. | D16: Experiential Amplification | E16: {=IFERROR(INDEX(s001_insights!F:F,MATCH("s001M01"&A16,s001_insights!A:A,0)),"")} | F16: {=IFERROR(INDEX(s002_insights!F:F,MATCH("s002M01"&A16,s002_insights!A:A,0)),"")} -> TK05 Practised Motor and Tool-Operation Skill TK06 Trained Sensory and Perceptual Recognition | G16: {=IFERROR(INDEX(s003_insights!F:F,MATCH("s003M01"&A16,s003_insights!A:A,0)),"")} | H16: =3-COUNTIF(E16:G16,"") -> 1

Sheet TP Perspectives
A1: ID | B1: Practice | C1: Retention Mechanism | D1: Sector coverage | E1: Relevant sectors | F1: Potential Pattern | G1: Potential Patterns
A2: TP01 | B2: Model-based Knowledge Representation and Simulation | C2: Digital Codification | D2: 2/3 | E2: Construction; Health Services | F2: TK Convergence: TK06 TK Divergence: TK05; TK10 | G2: Perceptual convergence with health-specific extension to motor skill and professional judgment
A3: TP03 | B3: Situated Experiential Learning through Extended Reality | C3: Experiential Amplification | D3: 3/3 | E3: Construction; Manufacturing; Health Services | F3: TK Convergence: TK05; TK06; TK07; TK08; TK10 TK Divergence: TK04; TK11 | G3: Strong embodied–perceptual convergence with sector-specific extensions of situated know-how
A4: TP04 | B4: Interactive Consequence Learning and Digital Feedback | C4: Experiential Amplification | D4: 2/3 | E4: Manufacturing; Health Services | F4: TK Convergence: None identified TK Divergence: TK05; TK10 | G4: Sector-divergent experiential feedback targeting motor skill and professional judgment
A5: TP06 | B5: Worker Activity and State Capture through Wearable Sensors and Cameras | C5: Digital Codification | D5: 2/3 | E5: Construction; Manufacturing | F5: TK Convergence: TK06; TK07 TK Divergence: TK04; TK05 | G5: Embodied–perceptual convergence with broader know-how capture in manufacturing
A6: TP07 | B6: Algorithmic Pattern Discovery and Prediction | C6: Digital Codification | D6: 3/3 | E6: Construction; Manufacturing; Health Services | F6: TK Convergence: TK06; TK10 TK Divergence: TK02; TK04; TK05 | G6: Perceptual convergence with sector-specific extensions to judgment, demonstration, motor skill, and unarticulated know-how
A7: TP08 | B7: Generative Knowledge Synthesis and Content Production | C7: Digital Codification | D7: 2/3 | E7: Construction; Manufacturing | F7: TK Convergence: TK12 TK Divergence: TK06; TK07 | G7: Organizational-practice convergence with manufacturing extension to embodied–perceptual knowledge
A8: TP09 | B8: Semantic Knowledge Structuring and Retrieval | C8: Digital Codification | D8: 3/3 | E8: Construction; Manufacturing; Health Services | F8: TK Convergence: TK05 TK Divergence: TK02; TK09; TK10; TK12 | G8: cross-industry recurrence with divergent knowledge targets
A9: TP10 | B9: Database-supported Project Knowledge Archiving | C9: Digital Codification | D9: 3/3 | E9: Construction; Manufacturing; Health Services | F9: TK Convergence: TK04; TK05 TK Divergence: TK02; TK09; TK10; TK11; TK12 | G9: cross-industry recurrence with strongly sector-divergent archival knowledge targets
A10: TP11 | B10: Collaborative Knowledge Co-creation through Digital Platforms | C10: Experiential Amplification | D10: 2/3 | E10: Manufacturing; Health Services | F10: TK Convergence: TK04 TK Divergence: TK02; TK09; TK10; TK12 | G10: Interpersonal and socially embedded know-how convergence with sector-specific professional and organizational extensions
A11: TP12 | B11: Multimedia and Blended Knowledge Internalization | C11: Experiential Amplification | D11: 3/3 | E11: Construction; Manufacturing; Health Services | F11: TK Convergence: TK05 TK Divergence: TK10; TK11 | G11: Strong motor-skill convergence with sector-specific social and professional extensions
A12: TP13 | B12: Criteria-based Performance Evaluation and Ranking | C12: Digital Codification | D12: 3/3 | E12: Construction; Manufacturing; Health Services | F12: TK Convergence: TK10 TK Divergence: TK05; TK12 | G12: Professional-judgment convergence with sector-specific motor and organizational extensions
... A14: TP16 | B14: Gamified Procedural and Scenario-based Learning | C14: Experiential Amplification | D14: 1/3 | E14: Manufacturing | F14: TK Convergence: None identified TK Divergence: TK05; TK06 | G14: Embodied–perceptual learning pattern

Sheet cross_sector_insights_tk
A1: ID | B1: Name | C1: Scope | D1: Collins TK Taxonomy | E1: s001:Construction | F1: s002:Manufacturing | G1: s003:Health Services | H1: filed | I1: Sectors
A2: TK02 | B2: Knowledge Conveyed Through Examples or Demonstration | C2: Knowledge transferred through cases, stories, simulations, examples, pointing, or practical demonstration because a sufficient verbal account has not been provided. | D2: Relational Tacit Knowledge | F2: TP07 Algorithmic Pattern Discovery and Prediction TP10 Database-supported Project Knowledge Archiving | G2: TP09 Semantic Knowledge Structuring and Retrieval TP11 Collaborative Knowledge Co-creation through Digital Platforms | H2: =3-COUNTIF(E2:G2,"") -> 2 | I2: Manufacturing; Health Services
A3: TK04 | B3: Unrecognized or Unarticulated Personal Know-how | C3: A person performs or decides effectively but has not consciously identified, reflected upon, or expressed the knowledge being used. | D3: Relational Tacit Knowledge | E3: TP10 Database-supported Project Knowledge Archiving | F3: TP03 Situated Experiential Learning through Extended Reality TP06 Worker Activity and State Capture through Wearable Sensors and Cameras TP07 Algorithmic Pattern Discovery and Prediction TP10 Database-supported Project Knowledge Archiving TP11 Collaborative Knowledge Co-creation through Digital Platforms | G3: TP11 Collaborative Knowledge Co-creation through Digital Platforms TP15 Distributed-Ledger-enabled Transaction Assurance and Traceability | H3: =3-COUNTIF(E3:G3,"") -> 3 | I3: Construction; Manufacturing; Health Services
A4: TK05 | B4: Practised Motor and Tool-Operation Skill | C4: Competence requiring learned bodily control and coordination during physical work or tool-mediated activity. | D4: Somatic Tacit Knowledge | E4: TP03 Situated Experiential Learning through Extended Reality TP09 Semantic Knowledge Structuring and Retrieval TP10 Database-supported Project Knowledge Archiving TP12 Multimedia and Blended Knowledge Internalization | F4: TP03 Situated Experiential Learning through Extended Reality TP04 Interactive Consequence Learning and Digital Feedback TP06 Worker Activity and State Capture through Wearable Sensors and Cameras TP07 Algorithmic Pattern Discovery and Prediction TP10 Database-supported Project Knowledge Archiving TP12 Multimedia and Blended Knowledge Internalization TP13 Criteria-based Performance Evaluation and Ranking TP16 Gamified Procedural and Scenario-based Learning | G4: TP01 Model-based Knowledge Representation and Simulation TP03 Situated Experiential Learning through Extended Reality TP09 Semantic Knowledge Structuring and Retrieval TP12 Multimedia and Blended Knowledge Internalization | H4: =3-COUNTIF(E4:G4,"") -> 3 | I4: Construction; Manufacturing; Health Services
A5: TK06 | B5: Trained Sensory and Perceptual Recognition | C5: A learned capacity to detect meaningful visual, auditory, tactile, spatial, or other sensory differences. | D5: Somatic Tacit Knowledge | E5: TP01 Model-based Knowledge Representation and Simulation TP03 Situated Experiential Learning through Extended Reality TP06 Worker Activity and State Capture through Wearable Sensors and Cameras TP07 Algorithmic Pattern Discovery and Prediction | F5: TP03 Situated Experiential Learning through Extended Reality TP06 Worker Activity and State Capture through Wearable Sensors and Cameras TP07 Algorithmic Pattern Discovery and Prediction TP08 Generative Knowledge Synthesis and Content Production TP16 Gamified Procedural and Scenario-based Learning | G5: TP01 Model-based Knowledge Representation and Simulation TP03 Situated Experiential Learning through Extended Reality TP07 Algorithmic Pattern Discovery and Prediction | H5: =3-COUNTIF(E5:G5,"") -> 3 | I5: Construction; Manufacturing; Health Services
A6: TK07 | B6: Embodied Posture, Balance, and Spatial Control | C6: Bodily competence involving posture, balance, orientation, movement, distance, positioning, or spatial awareness. | D6: Somatic Tacit Knowledge | E6: TP03 Situated Experiential Learning through Extended Reality TP06 Worker Activity and State Capture through Wearable Sensors and Cameras | F6: TP03 Situated Experiential Learning through Extended Reality TP06 Worker Activity and State Capture through Wearable Sensors and Cameras TP08 Generative Knowledge Synthesis and Content Production | H6: =3-COUNTIF(E6:G6,"") -> 2 | I6: Construction; Manufacturing
A7: TK08 | B7: Immediate Embodied Response to Changing Conditions | C7: Rapid bodily or neurophysiological response to hazards or changing conditions, often preceding complete conscious reasoning. | D7: Somatic Tacit Knowledge | E7: TP03 Situated Experiential Learning through Extended Reality | G7: TP03 Situated Experiential Learning through Extended Reality | H7: =3-COUNTIF(E7:G7,"") -> 2 | I7: Construction; Health Services
A8: TK09 | B8: Shared Professional Language and Contextual Meaning | C8: Understanding that depends on participation in a community sharing specialized terms, categories, expressions, narratives, and contextual meanings. | D8: Collective Tacit Knowledge | F8: TP11 Collaborative Knowledge Co-creation through Digital Platforms | G8: TP09 Semantic Knowledge Structuring and Retrieval TP10 Database-supported Project Knowledge Archiving | H8: =3-COUNTIF(E8:G8,"") -> 2 | I8: Manufacturing; Health Services
A9: TK10 | B9: Shared Professional Norms and Standards of Judgment | C9: Judgment grounded in collectively learned expectations about what is appropriate, acceptable, credible, safe, or legitimate. | D9: Collective Tacit Knowledge | E9: TP03 Situated Experiential Learning through Extended Reality TP07 Algorithmic Pattern Discovery and Prediction TP10 Database-supported Project Knowledge Archiving TP13 Criteria-based Performance Evaluation and Ranking | F9: TP12 Multimedia and Blended Knowledge Internalization TP13 Criteria-based Performance Evaluation and Ranking | G9: TP01 Model-based Knowledge Representation and Simulation TP03 Situated Experiential Learning through Extended Reality TP04 Interactive Consequence Learning and Digital Feedback TP07 Algorithmic Pattern Discovery and Prediction TP09 Semantic Knowledge Structuring and Retrieval TP11 Collaborative Knowledge Co-creation through Digital Platforms | H9: =3-COUNTIF(E9:G9,"") -> 3 | I9: Construction; Manufacturing; Health Services
A10: TK11 | B10: Informal Coordination, Communication, and Escalation Know-how | C10: Unwritten conventions governing coordination, communication, negotiation, signalling, collaboration, contact, and escalation within a group. | D10: Collective Tacit Knowledge | E10: TP10 Database-supported Project Knowledge Archiving TP12 Multimedia and Blended Knowledge Internalization | G10: TP03 Situated Experiential Learning through Extended Reality | H10: =3-COUNTIF(E10:G10,"") -> 2 | I10: Construction; Health Services
A11: TK12 | B11: Organizational Culture and Unwritten Working Practices | C11: Knowledge embedded in organizational identity, traditions, routines, authority relations, and historically developed ways of working. | D11: Collective Tacit Knowledge | E11: TP08 Generative Knowledge Synthesis and Content Production TP10 Database-supported Project Knowledge Archiving | F11: TP08 Generative Knowledge Synthesis and Content Production TP09 Semantic Knowledge Structuring and Retrieval TP11 Collaborative Knowledge Co-creation through Digital Platforms | G11: TP13 Criteria-based Performance Evaluation and Ranking | H11: =3-COUNTIF(E11:G11,"") -> 3 | I11: Construction; Manufacturing; Health Services

Sheet TK Perspectives
A1: ID | B1: Name | C1: Retention Taxonomy | D1: Sector coverage | E1: Relevant sectors | F1: Potential Pattern
A2: =cross_sector_insights_tk!A2 -> TK02 | B2: =cross_sector_insights_tk!B2 -> Knowledge Conveyed Through Examples or Demonstration | C2: =cross_sector_insights_tk!D2 -> Relational Tacit Knowledge | D2: =cross_sector_insights_tk!H2&"/3" -> 2/3 | E2: =cross_sector_insights_tk!I2 -> Manufacturing; Health Services | F2: TP Convergence: None identified TP Divergence: TP07; TP09; TP10; TP11
A3: =cross_sector_insights_tk!A3 -> TK04 | B3: =cross_sector_insights_tk!B3 -> Unrecognized or Unarticulated Personal Know-how | C3: =cross_sector_insights_tk!D3 -> Relational Tacit Knowledge | D3: =cross_sector_insights_tk!H3&"/3" -> 3/3 | E3: =cross_sector_insights_tk!I3 -> Construction; Manufacturing; Health Services | F3: TP Convergence: TP10; TP11 TP Divergence: TP03; TP06; TP07; TP15
A4: =cross_sector_insights_tk!A4 -> TK05 | B4: =cross_sector_insights_tk!B4 -> Practised Motor and Tool-Operation Skill | C4: =cross_sector_insights_tk!D4 -> Somatic Tacit Knowledge | D4: =cross_sector_insights_tk!H4&"/3" -> 3/3 | E4: =cross_sector_insights_tk!I4 -> Construction; Manufacturing; Health Services | F4: TP Convergence: TP03; TP09; TP10; TP12 TP Divergence: TP01; TP04; TP06; TP07; TP13; TP16
A5: =cross_sector_insights_tk!A5 -> TK06 | B5: =cross_sector_insights_tk!B5 -> Trained Sensory and Perceptual Recognition | C5: =cross_sector_insights_tk!D5 -> Somatic Tacit Knowledge | D5: =cross_sector_insights_tk!H5&"/3" -> 3/3 | E5: =cross_sector_insights_tk!I5 -> Construction; Manufacturing; Health Services | F5: TP Convergence: TP01; TP03; TP06; TP07 TP Divergence: TP08; TP16
A6: =cross_sector_insights_tk!A6 -> TK07 | B6: =cross_sector_insights_tk!B6 -> Embodied Posture, Balance, and Spatial Control | C6: =cross_sector_insights_tk!D6 -> Somatic Tacit Knowledge | D6: =cross_sector_insights_tk!H6&"/3" -> 2/3 | E6: =cross_sector_insights_tk!I6 -> Construction; Manufacturing | F6: TP Convergence: TP03; TP06 TP Divergence: TP08
A7: =cross_sector_insights_tk!A7 -> TK08 | B7: =cross_sector_insights_tk!B7 -> Immediate Embodied Response to Changing Conditions | C7: =cross_sector_insights_tk!D7 -> Somatic Tacit Knowledge | D7: =cross_sector_insights_tk!H7&"/3" -> 2/3 | E7: =cross_sector_insights_tk!I7 -> Construction; Health Services | F7: TP Convergence: TP03 TP Divergence: None identified
A8: =cross_sector_insights_tk!A8 -> TK09 | B8: =cross_sector_insights_tk!B8 -> Shared Professional Language and Contextual Meaning | C8: =cross_sector_insights_tk!D8 -> Collective Tacit Knowledge | D8: =cross_sector_insights_tk!H8&"/3" -> 2/3 | E8: =cross_sector_insights_tk!I8 -> Manufacturing; Health Services | F8: TP Convergence: None identified TP Divergence: TP09; TP10; TP11
A9: =cross_sector_insights_tk!A9 -> TK10 | B9: =cross_sector_insights_tk!B9 -> Shared Professional Norms and Standards of Judgment | C9: =cross_sector_insights_tk!D9 -> Collective Tacit Knowledge | D9: =cross_sector_insights_tk!H9&"/3" -> 3/3 | E9: =cross_sector_insights_tk!I9 -> Construction; Manufacturing; Health Services | F9: TP Convergence: TP03; TP07; TP13 TP Divergence: TP01; TP04; TP09; TP10; TP11; TP12
A10: =cross_sector_insights_tk!A10 -> TK11 | B10: =cross_sector_insights_tk!B10 -> Informal Coordination, Communication, and Escalation Know-how | C10: =cross_sector_insights_tk!D10 -> Collective Tacit Knowledge | D10: =cross_sector_insights_tk!H10&"/3" -> 2/3 | E10: =cross_sector_insights_tk!I10 -> Construction; Health Services | F10: TP Convergence: None identified TP Divergence: TP03; TP10; TP12
A11: =cross_sector_insights_tk!A11 -> TK12 | B11: =cross_sector_insights_tk!B11 -> Organizational Culture and Unwritten Working Practices | C11: =cross_sector_insights_tk!D11 -> Collective Tacit Knowledge | D11: =cross_sector_insights_tk!H11&"/3" -> 3/3 | E11: =cross_sector_insights_tk!I11 -> Construction; Manufacturing; Health Services | F11: TP Convergence: TP08 TP Divergence: TP09; TP10; TP11; TP13

Sheet s001_insights
A1: node_id | B1: category | C1: insight | D1: primary_retention_category | E1: retention_mechanism | F1: tacit_knowledge_retained | G1: evidence_chain
A2: s001M01TP03 | B2: Technology-enable Retention Mechanism | C2: Focal technology-enabled tacit knowledge retention approach. Situated Experiential Learning through Extended Reality is classified as Experience Amplification. The aggregated practice uses VR, AR, MR, CAVE, and hybrid environments to reconstruct consequential cues, let learners navigate or act, and return immediate sensory or instructional feedback (node_id:s001M01TP03). Its dominant function is rehearsal and situated perception 3D assets and logs are supporting representations rather than the principal retained object. Evidence chain (directional and bounded). The practice adopts Artificial Intelligence and Intelligent Computation (node_id:s001M01TE01) Human–Computer Interaction and Immersive Technologies such as Unity, HoloLens, Oculus, HTC VIVE, and CAVE (node_id:s001M01TE02) cyber-physical, modelling, sensing, mobile, and supporting tools (node_id:s001M01TE03 node_id:s001M01TE04 node_id:s001M01TE05 node_id:s001M01TE07 node_id:s001M01TE09). It transfers Trained Sensory and Perceptual Recognition (node_id:s001M01TK06) through clearer and interactive hazard visualization and transfers Shared Professional Norms and Standards of Judgment (node_id:s001M01TK10) through risk assessment, equipment choice, and consequence feedback. It also captures Practised Motor and Tool-Operation Skill, Embodied Posture and Spatial Control, and Immediate Embodied Response (node_id:s001M01TK05 node_id:s001M01TK07 node_id:s001M01TK08) through recorded craft sequences, VR behaviour, and practical performance assessment. Retention mechanism. Experience Amplification follows the mechanism reconstructed cues → learner action → feedback or consequence → stabilized experiential pattern. Cross-case evidence supports this pattern: AR and VR made hazards perceptible and improved identification virtual excavation enabled practical performance before and after training problem-first VR required selection under uncertainty and then displayed accident consequences. Long-term evidence is mixed. One VR cohort showed no significant knowledge decline after four weeks and problem-first VR outperformed direct instruction, yet another comparison found significant forgetting after four to five weeks, and long-term practical performance was not tested. Thus the graph supports stronger experiential learning and some retention, not uniform causal persistence. Tacit knowledge retained. The core retained knowledge is embodied hazard recognition and judgment: perceiving hazards, assessing severity and likelihood, choosing protective equipment, navigating space, and responding rapidly. Such knowledge is difficult to retain because passive instruction lacks interaction, learners forget, expertise levels differ, and context-dependent judgment resists full articulation (node_id:s001M01LI01 node_id:s001M01LI03 node_id:s001M01LI04 node_id:s001M01LI10). XR mitigates these limits by permitting safe failure, reproducing otherwise inaccessible or unethical disaster conditions, making consequences visible, and linking knowing to doing. It does not eliminate motivation or expertise-reversal effects. Conditions and constraints. The practice depends on regulatory and ethics controls, external connectivity, physical site conditions, retention-test timing, governance, technical resources, protected training time, participant availability, and task-aligned interface design (node_id:s001M01ED01 node_id:s001M01ED05 node_id:s001M01ED08 node_id:s001M01ED10 node_id:s001M01OD01 node_id:s001M01OD03 node_id:s001M01OD04 node_id:s001M01OD05 node_id:s001M01OD08). Constraints include cybersickness and withdrawal, age and working-memory differences, limited content coverage, interoperability and loading delays, scarce haptics and physical space, development workload, commercialization pressure, and narrow retention measures (node_id:s001M01LI02 node_id:s001M01LI03 node_id:s001M01LI04 node_id:s001M01LI05 node_id:s001M01LI06 node_id:s001M01LI08 node_id:s001M01LI12 node_id:s001M01LI13). Cross-case synthesis and theoretical statement. Heritage interpretation, construction hazard training, energy-use learning, and confined-space exercises are not separate focal practices here together they reveal a common experiential mechanism. Their complementarity also explains the limits: fidelity without accessible hardware excludes users, immersion without sound instructional design can overload them, and short-term performance without delayed workplace assessment leaves retention uncertain. Emerging XR retains tacit knowledge by amplifying situated experience and allowing safe, consequential practice, but only when governance, design, access, adaptation time, and repeated use convert immersive exposure into durable workplace judgment. | D2: Experience Amplification | E2: Extended-reality technologies retain tacit knowledge by reconstructing consequential workplace cues, enabling learners to act within simulated situations, and returning immediate sensory or instructional feedback. VR, AR, MR, and CAVE environments make hazards perceptible, support equipment selection and spatial navigation, permit safe failure, and reveal consequences that cannot be ethically recreated onsite. Repeated action stabilizes perceptual, motor, postural, response, and professional-judgment patterns. Across cases, hazard identification and practical performance improved, and some four-week persistence appeared, although forgetting was also observed. Durable retention therefore depends on sound instructional design, accessible hardware, adaptation time, governance, and repeated, task-aligned practice with delayed workplace assessment. | F2: TK05 Practised Motor and Tool-Operation Skill TK06 Trained Sensory and Perceptual Recognition TK07 Embodied Posture, Balance, and Spatial Control TK08 Immediate Embodied Response to Changing Conditions TK10 Shared Professional Norms and Standards of Judgment | G2: TE01 TE02 TE03 TE04 TE05 TE07 TE09 -> TP03 -> TK05 TK06 TK07 TK08 TK10
A3: s001M01TP12 | B3: Technology-enable Retention Mechanism | C3: Focal technology-enabled tacit knowledge retention approach. Multimedia and Blended Knowledge Internalization is classified as Experience Amplification. It combines digital content, interactive media, online resources, and face-to-face or workplace activity so learners observe demonstrations, contribute, discuss, and apply knowledge (node_id:s001M01TP12). Its dominant function is strengthened experience and social participation, not merely the storage of content. Evidence chain (directional and bounded). Interactive classroom technologies such as Vevox and Mentimeter (node_id:s001M01TE02), Moodle (node_id:s001M01TE04), Padlet and YouTube (node_id:s001M01TE07), and eBooks within the ambiguous technology class (node_id:s001M01TE09) are adopted by Multimedia and Blended Internalization (node_id:s001M01TP12). The practice transfers Practised Motor and Tool-Operation Skill (node_id:s001M01TK05) through technology-supported practical learning and demonstration, and transfers Informal Coordination, Communication, and Escalation Know-how (node_id:s001M01TK11) through group learning. The latter relationship is directly expressed as learning from groupmates. Retention mechanism. Experience Amplification follows digital demonstration and content → active discussion or problem solving → application and peer feedback → internalization. YouTube scaffolding visualization and interactive platforms supply examples face-to-face participation and small-group exchange allow learners to interpret and rehearse them. The graph reports that 82 percent of respondents felt more involved and that flipped and block structures can reduce cognitive overload. These are plausible enabling outcomes, but no delayed retention test is linked to this practice, so long-term persistence remains unproven. Tacit knowledge retained. The target knowledge is practical digital and construction skill plus the unwritten coordination habits learned through peer collaboration. These are hard to retain where craft inheritance is interrupted, formats fragment, and formal documentation misses interpersonal nuance (node_id:s001M01LI05 node_id:s001M01LI10). Blended learning mitigates passive listening and the theory–practice gap (node_id:s001M01LI04) by making learners active contributors, but it does not automatically resolve absenteeism, unequal participation, or differences in prior education. Conditions and constraints. The practice depends on institutional sponsorship (node_id:s001M01OD02), protected schedules and manageable class sizes (node_id:s001M01OD04), student engagement and co-creation (node_id:s001M01OD05), industry-aligned curriculum design (node_id:s001M01OD08), and the sociocultural diversity of learners (node_id:s001M01ED03). Student absence is an incompletely specified external dependency (node_id:s001M01ED10). Diverse backgrounds, scheduling pressure, and group dynamics constrain results (node_id:s001M01LI03 node_id:s001M01LI08 node_id:s001M01LI09). Cross-case synthesis. Heritage craft display and higher-education blended learning contribute different components to the aggregate. The former suggests that lightweight digital presentation can extend access to craft processes, while the latter shows how interactive platforms, peer collaboration, and block teaching support internalization. The strongest tacit link is not the medium itself but participation around the medium: students interpret demonstrations, compare perspectives, and learn coordination from groupmates. Content availability without these interactions would be codified access rather than experiential retention. Integrative theoretical statement. Blended technologies retain tacit knowledge primarily by amplifying socially situated practice. Digital content becomes durable know-how only when learners participate, receive contextual guidance, obtain feedback, and repeatedly translate representations into coordinated action. Evidence of later performance across different projects would strengthen the retention claim beyond reported engagement and immediate understanding. Institutional support and curriculum alignment are therefore not background variables but constitutive parts of the mechanism they determine whether multimedia is consumed passively or becomes a scaffold for practice. | D3: Experience Amplification | E3: Blended technologies retain tacit knowledge by combining demonstrations with active discussion, problem solving, workplace application, and peer feedback. Videos, eBooks, Moodle, Padlet, and interactive classroom tools supply examples and reference points face-to-face and small-group activity lets learners interpret, rehearse, and adapt them. The mechanism amplifies socially situated experience, supporting practical skill and informal coordination rather than merely distributing content. Reported involvement and reduced cognitive overload indicate enabling conditions, but delayed retention remains untested. Persistence therefore depends on institutional sponsorship, protected schedules, manageable groups, inclusive participation, industry-aligned curriculum, and repeated application across projects passive consumption would amount only to codified access. | F3: TK05 Practised Motor and Tool-Operation Skill TK11 Informal Coordination, Communication, and Escalation Know-how | G3: TE02 TE04 TE07 TE09 -> TP12 -> TK05 TK11
A4: s001M01TP01 | B4: Technology-enable Retention Mechanism | C4: Focal technology-enabled tacit knowledge retention approach. Model-based Knowledge Representation and Simulation is classified as Digital Codification. Across the aggregated cases, BIM, 3D/4D models, computational scenarios, and virtual models translate spatial arrangements, construction sequences, hazards, and performance relationships into inspectable representations (node_id:s001M01TP01). The dominant retention function is therefore the preservation and reuse of a model, not repeated embodied rehearsal. Immersive presentation is a secondary delivery capability. Evidence chain (directional and bounded). Human–Computer Interaction and Immersive Technologies, including Unity, CAVE, Navisworks, and SketchUp (node_id:s001M01TE02), together with Data, Information, and Knowledge Systems such as BIM, AutoCAD, Rhinoceros, Revit, and a centralized database (node_id:s001M01TE04), and the specifically evidenced EnergyPlus tool within the ambiguous technology class (node_id:s001M01TE09), are adopted by Model-based Knowledge Representation and Simulation (node_id:s001M01TP01). The only non-ambiguous retention edge is Technology-enabled Practice → captures → Trained Sensory and Perceptual Recognition (node_id:s001M01TK06): 4D BIM simulation made activity-based hazards identifiable at design stage. The linked tacit knowledge is difficult to retain where passive instruction fails to stimulate skill transfer (node_id:s001M01LI04) and where manual rules or sparse data omit complex safety cues (node_id:s001M01LI05). The secondary chain is Technology-enabled Practice → depends on → Culture, Trust and Relational Climate (node_id:s001M01OD06), evidenced by the need for a consciously maintained safety and continuous-improvement culture. Retention mechanism. Digital Codification is justified because the practice externalizes expert hazard recognition into persistent geometry, schedules, risk records, and simulated sequences that can be inspected before work and revisited across projects. The graph distinguishes adoption from retention: the presence of modelling software establishes technical availability the capture edge to hazard-recognition knowledge establishes codification effective retention is strongest only where the centralized OHS database preserves and shares information for later projects. Tacit knowledge retained. The retained capability is trained perceptual recognition: noticing activity-based hazards in spatial and temporal context (node_id:s001M01TK06). This know-how is hard to verbalize exhaustively and conventional instruction leaves a knowledge-to-practice gap. The model mitigates that gap by making otherwise latent relationships among design, sequence, and hazard visible, while the database component counters loss of OHS information as personnel change (node_id:s001M01LI10). BIM also reduced stakeholder document-approval time in one case, mitigating part of the workload constraint (node_id:s001M01LI08), but that efficiency is not itself evidence of knowledge retention. Conditions and constraints. Implementation is constrained by capital and maintenance cost (node_id:s001M01LI07), limited BIM and OHS-model expertise (node_id:s001M01LI08), and the quality limits attached to formal rules and data (node_id:s001M01LI05). The dependence on safety and learning culture means that a technically available model may remain unused or fail to become organizational memory. Cross-case synthesis and theoretical statement. The cases contribute different components rather than different practices: heritage and apartment models establish representation, BIM cases establish design communication and sequence simulation, and the OHS cases connect modelling to hazard recognition and future-project reuse. The strongest retention evidence comes from the OHS chain because it joins simulation to a named tacit capability and then to centralized continuity. The energy and presentation examples demonstrate adoption and representation but do not independently prove retention. Emerging modelling technologies therefore retain tacit know-how when organizations convert situated expert recognition into a governed, revisitable representation, preserve the related decisions and lessons, and embed the artefact in continuous-improvement routines adoption without capture, database continuity, and cultural use remains only technological deployment. | D4: Digital Codification | E4: Modeling technologies retain tacit hazard-recognition knowledge by translating experts’ spatial, sequencing, and performance judgments into BIM, 3D/4D models, simulations, and linked risk records. These representations make latent relationships visible before construction, allow teams to inspect activity-based hazards, and preserve decisions for later projects. Centralized OHS databases strengthen continuity by storing and sharing the modeled information beyond individual staff tenure. Retention depends on expert validation, adequate modeling competence, governed data, and a safety-oriented continuous-improvement culture. Software adoption alone is insufficient: the mechanism becomes retention only when captured cues remain revisitable, interpretable, and routinely reused in design reviews, training, and project learning. | F4: TK06 Trained Sensory and Perceptual Recognition | G4: TE02 TE04 TE09 -> TP01 -> TK06
A5: s001M01TP06 | B5: Technology-enable Retention Mechanism | C5: Focal technology-enabled tacit knowledge retention approach. Worker Activity and State Capture through Wearable Sensors and Cameras is classified as Digital Codification. IMUs, wearable cameras, eye tracking, and video analysis intercept embodied work and convert posture, movement, gaze, external load, and task context into measurable records (node_id:s001M01TP06). The durable data representation is the dominant function feedback or rehearsal is not the primary mechanism. Evidence chain (directional and bounded). Human–Computer Interaction and Immersive Technologies, specifically HoloLens eye and head gaze capture (node_id:s001M01TE02), and Imaging, Sensing, and Perception Technologies, including multiple IMUs and wearable cameras (node_id:s001M01TE05), are adopted by Worker Activity and State Capture (node_id:s001M01TP06). The practice captures Trained Sensory and Perceptual Recognition (node_id:s001M01TK06) by detecting abnormal or hazardous postures, and it captures and evaluates Embodied Posture, Balance, and Spatial Control (node_id:s001M01TK07) by combining sensor posture with video-observed hand weight to estimate lumbar load. The associated knowledge is hard to capture uniformly because individual bodies differ and motivation affects workplace transfer (node_id:s001M01LI03 node_id:s001M01LI04). Retention mechanism. Digital Codification operates as activity → sensor/video trace → calculated posture or workload representation → comparison and later assessment. This preserves aspects of embodied know-how that workers may not verbalize, including how they position themselves and handle loads. It remains a partial codification: the data represent observable posture and state, not the full situated reasons behind a worker's action. The graph supports capture and evaluation more strongly than transfer or long-term reuse. Tacit knowledge retained. The focal content is perceptual hazard recognition and embodied posture control. Video and IMU measurements make otherwise fleeting bodily performance inspectable, enabling organizations to identify risky patterns and potentially design assistive technology. The practice mitigates a measurement weakness only conditionally: collecting more observations may improve workload estimates, but one study found no clear correlation between workload and assistive technologies and an unclear target population (node_id:s001M01LI13). Thus the graph does not demonstrate that recorded data became retained operational know-how. Conditions and constraints. Regulatory evaluation frameworks such as OWAS, RULA, REBA, and HOHSRAM provide an external interpretation standard (node_id:s001M01ED01) access to actual job sites supplies the physical context needed to relate sensors to work (node_id:s001M01ED08) and individual–technology compatibility shapes implementation (node_id:s001M01OD08). Mixed learner characteristics, narrow samples, and uncertain construct validity constrain generalization (node_id:s001M01LI03 node_id:s001M01LI13 node_id:s001M01LI14). Cross-case synthesis and theoretical statement. The workload and mixed-reality cases identify complementary forms of capture: body-worn devices record the worker, while eye and head tracking record attention inside an instructional environment. Both depend on interpretation standards and representative populations. A measured posture may indicate risk without explaining the practical trade-off that produced it, and gaze may indicate attention without establishing comprehension. Retention therefore requires expert annotation, comparison over time, and feedback into redesigned tasks or training. Longitudinal evidence showing safer later performance would be needed to close the chain from measurement to retained capability. Wearables support tacit-knowledge retention when ephemeral embodied action is converted into interpretable, governed records and then fed back into practice sensing alone records performance without proving organizational learning. | D5: Digital Codification | E5: Wearable sensors and cameras retain tacit knowledge by converting fleeting embodied activity into durable, interpretable records. IMUs, wearable video, eye tracking, and workload analysis capture posture, movement, gaze, load handling, and task context that workers may struggle to verbalize. Analysts can compare traces over time, identify hazardous patterns, and use the findings to redesign work, assistive technology, or training. The codification remains partial because measurements represent observable action, not every situated reason behind it. Retention therefore requires expert annotation, regulatory interpretation, representative samples, privacy safeguards, and feedback into practice sensing alone documents performance without demonstrating transfer or safer long-term behavior. | F5: TK06 Trained Sensory and Perceptual Recognition TK07 Embodied Posture, Balance, and Spatial Control | G5: TE02 TE05 -> TP06 -> TK06 TK07
A6: s001M01TP07 | B6: Technology-enable Retention Mechanism | C6: Focal technology-enabled tacit knowledge retention approach. Algorithmic Pattern Discovery and Prediction is classified as Digital Codification. AI, machine learning, NLP, statistical learning, and rules transform unstructured reports, gaze data, and operating measurements into features, classifications, forecasts, and detected patterns (node_id:s001M01TP07). The dominant function is the extraction and durable representation of latent regularities, not situated rehearsal. Evidence chain (directional and bounded). Artificial Intelligence and Intelligent Computation—NLP, deep learning, CNNs, Word2Vec, GPT-4o extraction, ensemble classifiers, and predictive analytics—is the principal adopted technology (node_id:s001M01TE01), with Python grouped as a supporting ambiguous technology (node_id:s001M01TE09). The practice captures and transfers Trained Sensory and Perceptual Recognition (node_id:s001M01TK06) by extracting accident precursors and non-explicit semantic associations, and captures Shared Professional Norms and Standards of Judgment (node_id:s001M01TK10) by identifying the importance of risk factors, scenario-specific hazards, temporary support, soil stability, and material fatigue. These knowledge types are difficult to retain because manual rules omit complex texts, classification is subjective, and contextual judgment resists full automation (node_id:s001M01LI05 node_id:s001M01LI08 node_id:s001M01LI10). Retention mechanism. Digital Codification proceeds from historical data → preprocessing and representation → learned pattern or prediction → retrievable classification and decision cue. Cross-case evidence supports automatic feature extraction from accident narratives, requirement extraction from bids, learner-pattern classification, and predictive monitoring. Algorithms reduce dependence on manually designed features and large-scale human classification, mitigating software/data barriers and workload (node_id:s001M01LI05 node_id:s001M01LI08). They also surface information for archiving and immediate sharing. Yet discovery is not automatically retention: the graph provides limited evidence that predictions were repeatedly used, validated, or embedded in routines. Tacit knowledge retained. The strongest retained content is latent safety recognition and professional risk judgment. Narrative phrases and CNN representations make antecedents that experts perceive implicitly available for comparison across reports. This can broaden organizational memory beyond individual recall. However, overlapping vocabulary produced misclassification, language specificity reduced portability, object-strike performance remained weak, and the theoretical framework had not become a practical tool. The data therefore support codification of candidate tacit patterns, not a complete replacement for expert interpretation. Conditions and constraints. The practice depends on representative corpora and integrated infrastructure (node_id:s001M01OD03), leadership sponsorship and safety-management commitment (node_id:s001M01OD02), a knowledge-sharing and safety culture (node_id:s001M01OD06), and, for heating prediction, climatic context (node_id:s001M01ED04). Constraints include data imbalance, OCR and format limits, infrastructure gaps, underutilization under authoritarian leadership, privacy risks, operational variability, and limited validation (node_id:s001M01LI05 node_id:s001M01LI06 node_id:s001M01LI09 node_id:s001M01LI10 node_id:s001M01LI11 node_id:s001M01LI13 node_id:s001M01LI14). Cross-case synthesis and theoretical statement. Accident classification offers the clearest codification chain because latent phrases are linked to named safety knowledge bid extraction, learner classification, project monitoring, and heating prediction show the broader analytical capability but not the same strength of retention evidence. The cases also expose a recurrent trade-off between scale and meaning: algorithms can process more traces than experts, yet their categories inherit corpus imbalance, language boundaries, labels, and infrastructure conditions. Algorithmic technologies retain tacit knowledge by converting dispersed experiential traces into reusable pattern representations, but those representations become actionable organizational memory only through expert validation, adequate data, leadership support, contestable classifications, and incorporation into real decisions. | D6: Digital Codification | E6: Algorithmic technologies retain tacit knowledge by transforming experience traces into reusable classifications, patterns, forecasts, and decision cues. AI, machine learning, and NLP preprocess accident narratives, gaze data, bid material, and operating measurements, then surface hidden precursors, semantic associations, and risk factors that manual rules may miss. These codified patterns can support search, monitoring, and professional judgment while reducing classification workload. However, discovery becomes organizational memory only when outputs are validated by experts, supported by representative data and infrastructure, and embedded in real decisions. Bias, privacy, context loss, weak leadership, or limited validation can otherwise preserve misleading patterns rather than knowledge. | F6: TK06 Trained Sensory and Perceptual Recognition TK10 Shared Professional Norms and Standards of Judgment | G6: TE01 TE09 -> TP07 -> TK06 TK10
