Workbook

Sheet construction
B2: Case ID | C2: Initial KG (Expandation by Multiple Sources) | F2: 1st Round (Schema Check) | G2: 2nd Round (FactCheck ) | H2: 3rd Round (Entity Alignment) | I2: Accepted Rate | J2: 4th Round (DTC )
B3: =sector_data!A2 -> c101 | C3: Entities | D3: Deepseek | E3: =sector_data!B2 -> 24 | F3: =sector_data!F2 -> 46 | G3: =sector_data!H2 -> 46 | H3: =sector_data!J2 -> 36 | I3: =sector_data!L2 -> 0.78 | J3: 0.85
D4: Gemini | E4: =sector_data!D2 -> 22
C5: Edges | D5: Deepseek | E5: =sector_data!C2 -> 59 | F5: =sector_data!G2 -> 65 | G5: =sector_data!I2 -> 58 | H5: =sector_data!K2 -> 58 | I5: =sector_data!M2 -> 0.69
D6: Gemini | E6: =sector_data!E2 -> 25
B7: =sector_data!A3 -> c102 | C7: Entities | D7: Deepseek | E7: =sector_data!B3 -> 45 | F7: =sector_data!F3 -> 56 | G7: =sector_data!H3 -> 53 | H7: =sector_data!J3 -> 51 | I7: =sector_data!L3 -> 0.85 | J7: 0.85
D8: Gemini | E8: =sector_data!D3 -> 15
C9: Edges | D9: Deepseek | E9: =sector_data!C3 -> 71 | F9: =sector_data!G3 -> 90 | G9: =sector_data!I3 -> 67 | H9: =sector_data!K3 -> 67 | I9: =sector_data!M3 -> 0.71
D10: Gemini | E10: =sector_data!E3 -> 24
B11: =sector_data!A4 -> c103 | C11: Entities | D11: Deepseek | E11: =sector_data!B4 -> 51 | F11: =sector_data!F4 -> 71 | G11: =sector_data!H4 -> 68 | H11: =sector_data!J4 -> 53 | I11: =sector_data!L4 -> 0.68 | J11: 0.85
D12: Gemini | E12: =sector_data!D4 -> 27
C13: Edges | D13: Deepseek | E13: =sector_data!C4 -> 64 | F13: =sector_data!G4 -> 90 | G13: =sector_data!I4 -> 77 | H13: =sector_data!K4 -> 74 | I13: =sector_data!M4 -> 0.76
D14: Gemini | E14: =sector_data!E4 -> 34
B15: =sector_data!A5 -> c104 | C15: Entities | D15: Deepseek | E15: =sector_data!B5 -> 42 | F15: =sector_data!F5 -> 56 | G15: =sector_data!H5 -> 48 | H15: =sector_data!J5 -> 39 | I15: =sector_data!L5 -> 0.62 | J15: 0.85
D16: Gemini | E16: =sector_data!D5 -> 21
C17: Edges | D17: Deepseek | E17: =sector_data!C5 -> 59 | F17: =sector_data!G5 -> 90 | G17: =sector_data!I5 -> 59 | H17: =sector_data!K5 -> 47 | I17: =sector_data!M5 -> 0.52
D18: Gemini | E18: =sector_data!E5 -> 31
B19: =sector_data!A6 -> c105 | C19: Entities | D19: Deepseek | E19: =sector_data!B6 -> 33 | F19: =sector_data!F6 -> 44 | G19: =sector_data!H6 -> 39 | H19: =sector_data!J6 -> 30 | I19: =sector_data!L6 -> 0.67 | J19: 0.85
D20: Gemini | E20: =sector_data!D6 -> 12
C21: Edges | D21: Deepseek | E21: =sector_data!C6 -> 51 | F21: =sector_data!G6 -> 64 | G21: =sector_data!I6 -> 51 | H21: =sector_data!K6 -> 47 | I21: =sector_data!M6 -> 0.71
D22: Gemini | E22: =sector_data!E6 -> 15
B23: =sector_data!A7 -> c106 | C23: Entities | D23: Deepseek | E23: =sector_data!B7 -> 0 | F23: =sector_data!F7 -> 26 | G23: =sector_data!H7 -> 24 | H23: =sector_data!J7 -> 24 | I23: =sector_data!L7 -> 0.92 | J23: 0.85
D24: Gemini | E24: =sector_data!D7 -> 26
C25: Edges | D25: Deepseek | E25: =sector_data!C7 -> 0 | F25: =sector_data!G7 -> 23 | G25: =sector_data!I7 -> 19 | H25: =sector_data!K7 -> 19 | I25: =sector_data!M7 -> 0.7
D26: Gemini | E26: =sector_data!E7 -> 27
B27: =sector_data!A8 -> c107 | C27: Entities | D27: Deepseek | E27: =sector_data!B8 -> 44 | F27: =sector_data!F8 -> 47 | G27: =sector_data!H8 -> 45 | H27: =sector_data!J8 -> 42 | I27: =sector_data!L8 -> 0.63 | J27: 0.85
D28: Gemini | E28: =sector_data!D8 -> 23
C29: Edges | D29: Deepseek | E29: =sector_data!C8 -> 46 | F29: =sector_data!G8 -> 46 | G29: =sector_data!I8 -> 40 | H29: =sector_data!K8 -> 35 | I29: =sector_data!M8 -> 0.45
D30: Gemini | E30: =sector_data!E8 -> 32
B31: =sector_data!A9 -> c108 | C31: Entities | D31: Deepseek | E31: =sector_data!B9 -> 42 | F31: =sector_data!F9 -> 57 | G31: =sector_data!H9 -> 52 | H31: =sector_data!J9 -> 40 | I31: =sector_data!L9 -> 0.66 | J31: 0.85
D32: Gemini | E32: =sector_data!D9 -> 19
C33: Edges | D33: Deepseek | E33: =sector_data!C9 -> 49 | F33: =sector_data!G9 -> 71 | G33: =sector_data!I9 -> 57 | H33: =sector_data!K9 -> 48 | I33: =sector_data!M9 -> 0.62
D34: Gemini | E34: =sector_data!E9 -> 28
B35: =sector_data!A10 -> c109 | C35: Entities | D35: Deepseek | E35: =sector_data!B10 -> 22 | F35: =sector_data!F10 -> 34 | G35: =sector_data!H10 -> 31 | H35: =sector_data!J10 -> 25 | I35: =sector_data!L10 -> 0.74 | J35: 0.85
D36: Gemini | E36: =sector_data!D10 -> 12
C37: Edges | D37: Deepseek | E37: =sector_data!C10 -> 26 | F37: =sector_data!G10 -> 40 | G37: =sector_data!I10 -> 34 | H37: =sector_data!K10 -> 29 | I37: =sector_data!M10 -> 0.71
D38: Gemini | E38: =sector_data!E10 -> 15
B39: =sector_data!A11 -> 0 | C39: Entities | D39: Deepseek | E39: =sector_data!B11 -> 0 | F39: =sector_data!F11 -> 0 | G39: =sector_data!H11 -> 0 | H39: =sector_data!J11 -> 0 | I39: =sector_data!L11 -> 0 | J39: 0.85
D40: Gemini | E40: =sector_data!D11 -> 0
C41: Edges | D41: Deepseek | E41: =sector_data!C11 -> 0 | F41: =sector_data!G11 -> 0 | G41: =sector_data!I11 -> 0 | H41: =sector_data!K11 -> 0 | I41: =sector_data!M11 -> 0
...

Sheet sector_data
A1: case_id | B1: Initial_deepseek_nodes | C1: Initial_deepseek_relations | D1: Initial_gemini_nodes | E1: Initial_gemini_relations | F1: r1_nodes | G1: r1_relations | H1: r2_nodes | I1: r2_relations | J1: r3_nodes | K1: r3_relations | L1: node_accepted_rate | M1: relation_accepted_rate
A2: c101 | B2: 24 | C2: 59 | D2: 22 | E2: 25 | F2: 46 | G2: 65 | H2: 46 | I2: 58 | J2: 36 | K2: 58 | L2: 0.78 | M2: 0.69
A3: c102 | B3: 45 | C3: 71 | D3: 15 | E3: 24 | F3: 56 | G3: 90 | H3: 53 | I3: 67 | J3: 51 | K3: 67 | L3: 0.85 | M3: 0.71
A4: c103 | B4: 51 | C4: 64 | D4: 27 | E4: 34 | F4: 71 | G4: 90 | H4: 68 | I4: 77 | J4: 53 | K4: 74 | L4: 0.68 | M4: 0.76
A5: c104 | B5: 42 | C5: 59 | D5: 21 | E5: 31 | F5: 56 | G5: 90 | H5: 48 | I5: 59 | J5: 39 | K5: 47 | L5: 0.62 | M5: 0.52
A6: c105 | B6: 33 | C6: 51 | D6: 12 | E6: 15 | F6: 44 | G6: 64 | H6: 39 | I6: 51 | J6: 30 | K6: 47 | L6: 0.67 | M6: 0.71
A7: c106 | B7: 0 | C7: 0 | D7: 26 | E7: 27 | F7: 26 | G7: 23 | H7: 24 | I7: 19 | J7: 24 | K7: 19 | L7: 0.92 | M7: 0.7
A8: c107 | B8: 44 | C8: 46 | D8: 23 | E8: 32 | F8: 47 | G8: 46 | H8: 45 | I8: 40 | J8: 42 | K8: 35 | L8: 0.63 | M8: 0.45
A9: c108 | B9: 42 | C9: 49 | D9: 19 | E9: 28 | F9: 57 | G9: 71 | H9: 52 | I9: 57 | J9: 40 | K9: 48 | L9: 0.66 | M9: 0.62
A10: c109 | B10: 22 | C10: 26 | D10: 12 | E10: 15 | F10: 34 | G10: 40 | H10: 31 | I10: 34 | J10: 25 | K10: 29 | L10: 0.74 | M10: 0.71
